<mujoco model="inverted pendulum">
    <compiler angle="radian"/>
    <option gravity='0 0 -9.806' timestep="0.0005" iterations="50">        
        <flag sensornoise="enable"/>
    </option>
    <asset>
        <texture type='skybox' builtin='gradient' width='128' height='128' rgb1='0.4 0.6 0.8' rgb2='0 0 0'/>
        <texture name='plane' type='2d' builtin='checker' rgb1='0.2 0.2 0.2' rgb2='0.3 0.3 0.3' width='512' height='512'/>
        <material name='plane' reflectance='0.0' texture='plane' texrepeat='1 1' texuniform='true'/>
    </asset>

    <worldbody>
        <light directional="true" cutoff="4" exponent="20" diffuse="1 1 1" specular="0 0 0" pos=".9 .3 2.5" dir="-.9 -.3 -2.5 "/>
        <geom name='floor' type='plane' conaffinity='15' condim='3' material='plane' pos='0 0 0' size='1 1 0.125'/>
        <body name="beambody" pos="0 0 .2">
            <geom name="base" pos="0 0 0" type="capsule" size=".01 .2" rgba='1 0 0 1' euler="1.57 0 0" mass='0.001'/>
            <joint name="pivot" pos="0 0 0" axis="0 1 0" limited="false" damping=".05"/>
            <body name="rodbody" pos="0 0 0">
                <geom name="rodgeom" type="cylinder" rgba='1 1 1 1' pos="0 0 0.2" size=".005 .2" mass="0.001"/>
                <body name="ballbody" pos="0 0 0.4">
                    <geom name="ballgeom" type="sphere" rgba='1 1 1 1' pos="0 0 0" size=".05" mass="10"/>
                    <site name='ballsite' pos='0 0 0' size='0.01'/>
                </body>
            </body>
        </body>
    </worldbody>

    <actuator>
        <motor joint='pivot' name='motor' gear="1" forcelimited="true" forcerange="-10 10"/>
    </actuator>

    <sensor>
        <!-- <jointpos name="encoder" joint="pivot" noise="0.001"/> -->
        <jointpos name="encoder" joint="pivot"/>
    </sensor>

</mujoco>